Workbook

Sheet Data_Sources
A1: Ashok Leyland Limited - Credit Assessment: Data Sources Used (Assignment Point 3)
A2: Company: Ashok Leyland Ltd (NSE: ASHOKLEY), Hinduja Group flagship; commercial-vehicle OEM. Basis: STANDALONE financial statements, ₹ crore, FY24-FY26 (years ending 31 March). Sources: Annual Reports 2023-24, 2024-25 and 2025-26 (uploaded). Page numbers are the printed page numbers of each annual report.
A4: Source | B4: What was extracted | C4: Where (printed pages) | D4: Key evidence found | E4: Why it matters for credit | F4: Workbook sheet
A5: 1. Latest annual report + two prior years (FY24, FY25, FY26) | B5: Revenue, EBITDA, PAT, borrowings, lease liabilities, finance cost (with break-up), CFO, capex, dividends, tax paid, full balance sheet | C5: FY26 AR: BS p.122, P&L p.123, CF p.124-125, Note 2.5 p.169 FY25 AR: BS p.112, P&L p.113, CF p.114-115, Note 2.5 p.158 FY24 AR: BS p.116, P&L p.117, CF p.118-119 | D5: Revenue ₹38,367 cr → ₹38,753 cr → ₹44,007 cr; PAT ₹2,618 cr → ₹3,303 cr → ₹3,566 cr. Total debt incl. leases fell from ₹2,299 cr to ₹1,195 cr while cash and liquid investments rose, turning the company net-cash. Reported CFO (₹2,503 / ₹7,819 / ₹4,792 cr) is distorted by a ₹1,453 cr interim-dividend bank-account swing between FY24 and FY25, so an adjusted CFO is used. Capex doubled from ₹496 cr to ₹1,050 cr. FY26 PAT absorbed a one-off ₹308 cr labour-code charge. | E5: A three-year trend shows whether deleveraging and margin gains are structural or one-off; adjustments remove timing distortions before ratios are read. | F5: Financials, Ratios
A6: 2. Management Discussion & Analysis | B6: Industry volumes and outlook, demand drivers, market share, competition, stated risks and threats | C6: FY26 AR p.52-58 (industry table p.54, risk section p.56-57) FY25 AR p.48 onward FY24 AR p.60 onward | D6: Domestic CV industry hit a record ~10.8 lakh units in FY26 (+12.6%), with a weak H1 and a strong H2 after the GST cut on CVs from 28% to 18% (Sept-2025). Ashok Leyland's M&HCV share slipped from 31.1% (FY24) to 30.7% (FY25) to 30.3% (FY26); it leads buses (~34%) and hit a record LCV share (Vahan 12.7%). Exports rose 18.5% to 18,082 units; aftermarket revenue about ₹4,450 cr. Management flags West Asia/crude risk, tariffs, emission-compliance costs, electric 3-wheeler substitution in LCVs, volatile export markets and delays in government capex. MHCV truck volumes were flat for three years before FY26, which confirms cyclicality. | E6: Places the ratios in the CV cycle: FY26 is an up-cycle year, so leverage headroom must be tested against a downturn. | F6: Data_Sources (qualitative), Financials memo
A7: 3. Notes to Accounts | B7: Borrowings by instrument, security, repayment terms, current maturities, covenants, contingent liabilities, guarantees, commitments, related-party dealings | C7: FY26 AR: Notes 1.16 p.161, 1.21 p.163, 1.11B p.157, 3.8 RPT p.193-199, 3.9 p.200-201, 3.10 p.201, 3.11-3.12 p.202-203 FY25 AR: 1.16 p.151, 1.21 p.153, 3.8 p.181, 3.9 p.188-189, 3.11 p.190 FY24 AR: 1.16 p.154, 1.21 p.156, 3.9 p.187, 3.11 p.188 | D7: FY26 debt consists only of secured bank term loans, one ₹200 cr 7.30% NCD (bullet 17-Mar-2027), a ₹150 cr short-term loan and an interest-free sales-tax loan; the weighted cost is 6.83%. All covenants were met, and they include rating and promoter-holding triggers. Contingent liabilities are modest at ₹343 cr, mostly indirect-tax disputes. Guarantees for subsidiaries total ₹786 cr, mainly Switch Mobility UK (₹633 cr), whose UK manufacturing was discontinued in FY26. Continuing support to loss-making EV subsidiaries: ₹499 cr application money to Optare (FY25) and a ₹371 cr investment (FY26). Related-party items include ICDs to Hinduja group entities (up to ₹100 cr each during FY26, nil at year-end), dividends of ₹933 cr to the promoter, and an unquantified End-of-Life-Vehicle EPR obligation. | E7: The notes carry the strongest credit evidence: hidden obligations, security, covenant triggers and group cash leakage that the headline ratios do not show. | F7: Debt_Analysis (A, F, H), Ratios §7
A8: 4. Financial risk / liquidity disclosure (Note 3.6) | B8: Contractual maturity bands, undrawn lines, CP headroom, fixed/floating mix, rate sensitivity, FX exposure and hedging | C8: FY26 AR: capital mgmt p.183, FX p.183-185, interest rate p.186, liquidity p.187-188 FY25 AR p.171-176 FY24 AR p.172-176 | D8: Borrowing outflows due within 1 year: ₹1,234 cr (FY24), ₹614 cr (FY25), ₹698 cr (FY26). FY26 has undrawn bank lines of ₹2,854 cr plus a ₹2,000 cr CP option. Floating-rate debt is only ₹403 cr, and a 25 bp move changes profit by about ₹1 cr. Net FX exposure is small and largely hedged with forwards. | E8: Shows refinancing and liquidity risk: whether near-term maturities can be met from cash and lines without market access. | F8: Debt_Analysis (B, C, D, G)
A9: 5. Consolidated financial statements (supplementary) | B9: Group borrowings, equity, finance cost; structure of Hinduja Leyland Finance (HLF) | C9: FY26 AR p.220-221, Board's Report p.22 (HLF-NDL merger scheme) FY25 AR p.208-209 | D9: Consolidated borrowings of about ₹63,650 cr (FY26) are overwhelmingly HLF's NBFC debt, against standalone borrowings of about ₹1,152 cr. A scheme to merge HLF into NDL Ventures is awaiting NCLT approval. | E9: Justifies standalone analysis and highlights group-support and contagion risk. | F9: Consolidated_View
A10: 6. CRA rationale (after own view only) | B10: Strengths, weaknesses, rating sensitivities, liquidity view | C10: Not consulted yet - deliberately, per integrity rule | D10: To be read only after the independent assessment and lending decision are finished, and used only for the one-page comparison. | E10: Tests own judgement against the agency's view; not a source for copying. | F10: Later stage
A12: Workbook legend
A13: Blue text | B13: Hard-coded input copied from the annual report (source given beside it)
A14: Black text | B14: Formula / calculation
A15: Green text | B15: Link pulled from another sheet
A16: Check rows | B16: Rows labelled 'Check' should show '-' (zero); they tie extracted numbers back to report totals
A18: Sheets
A19: Financials | B19: Three-year extracted P&L, balance sheet, cash flow, finance-cost break-up, adjustments and memo items
A20: Ratios | B20: Profitability, leverage, coverage, cash-flow, liquidity, working-capital and off-balance-sheet ratios with trend flags
A21: Debt_Analysis | B21: Borrowings by instrument, debt mix, maturity bands, liquidity cover, contingent liabilities, FX, FY26 repayment schedule
A22: Consolidated_View | B22: Why standalone is used - group borrowings dominated by the NBFC subsidiary

Sheet Financials
A1: Ashok Leyland Limited - Standalone Financial Data Extracted (₹ crore)
A2: Blue = hard-coded input taken from the annual report; Black = formula. FY24 figures are the comparatives reported in the FY25 annual report (checked against the FY24 annual report, no restatement). FY25 figures are the comparatives in the FY26 annual report.
B4: Particulars (₹ crore) | C4: FY24 | D4: FY25 | E4: FY26 | F4: Source (Annual Report, Note, printed page)
A5: A. STATEMENT OF PROFIT AND LOSS
B6: Revenue from operations | C6: 38367.03 | D6: 38752.74 | E6: 44007.03 | F6: Statement of P&L - FY26 AR p.123; FY25 AR p.113; FY24 AR p.117
B7: Other income | C7: 246.57 | D7: 250.25 | E7: 315.17 | F7: Statement of P&L (Note 2.2)
B8: Cost of materials and services consumed | C8: 26916.54 | D8: 25711.74 | E8: 29722.68 | F8: Statement of P&L
B9: Purchases of stock-in-trade | C9: 1506.41 | D9: 1680.46 | E9: 1805.39 | F9: Statement of P&L
B10: Changes in inventories of FG, SIT and WIP | C10: -510.94 | D10: 230.58 | E10: -110.93 | F10: Statement of P&L (Note 2.3)
B11: Cost of goods sold (sum of above three) | C11: =SUM(C8:C10) -> 27912.01 | D11: =SUM(D8:D10) -> 27622.78 | E11: =SUM(E8:E10) -> 31417.14
B12: Employee benefits expense | C12: 2233.38 | D12: 2406.27 | E12: 2606.69 | F12: Statement of P&L (Note 2.4)
B13: Other expenses | C13: 3615.06 | D13: 3793.13 | E13: 4250.95 | F13: Statement of P&L (Note 2.7)
B14: Finance costs (as reported) | C14: 249.44 | D14: 216.91 | E14: 169.73 | F14: Statement of P&L (Note 2.5) - FY26 AR p.169; FY25 AR p.158
B15: Depreciation and amortisation expense | C15: 717.81 | D15: 719.34 | E15: 715.19 | F15: Statement of P&L (Note 2.6)
B16: Profit before exceptional items and tax | C16: 3885.9 | D16: 4244.56 | E16: 5162.5 | F16: Statement of P&L
B17: Exceptional items | C17: -93.72 | D17: 103.73 | E17: -348.48 | F17: Note 2.8 - FY26: labour-code impact (308.48) + litigation (40.00); FY25: fair-value gain on Hinduja Energy 120.53 - FY26 AR p.172; FY25 AR p.160
B18: Profit before tax | C18: 3792.18 | D18: 4348.29 | E18: 4814.02 | F18: Statement of P&L
B19: Total tax expense | C19: 1174.31 | D19: 1045 | E19: 1248.49 | F19: Statement of P&L
B20: Profit for the year (PAT) | C20: 2617.87 | D20: 3303.29 | E20: 3565.53 | F20: Statement of P&L
A22: B. DERIVED EARNINGS MEASURES (formulas)
B23: EBITDA (Revenue - COGS - Employee - Other expenses; excludes other income) | C23: =C6-C11-C12-C13 -> 4606.58 | D23: =D6-D11-D12-D13 -> 4930.56 | E23: =E6-E11-E12-E13 -> 5732.25 | F23: Operating EBITDA - other income excluded to keep treasury income out of debt-servicing capacity
B24: EBITDA including other income | C24: =C23+C7 -> 4853.15 | D24: =D23+D7 -> 5180.81 | E24: =E23+E7 -> 6047.42
B25: EBIT (EBITDA - D&A) | C25: =C23-C15 -> 3888.77 | D25: =D23-D15 -> 4211.22 | E25: =E23-E15 -> 5017.06
B26: Check: EBITDA + OI - D&A - FC should equal PBT before exceptional (0 = OK) | C26: =ROUND(C23+C7-C15-C14-C16,2) -> 0 | D26: =ROUND(D23+D7-D15-D14-D16,2) -> 0 | E26: =ROUND(E23+E7-E15-E14-E16,2) -> 0
A28: C. FINANCE COST BREAK-UP (Note 2.5)
B29: Interest expense (gross, before capitalisation) | C29: 192.66 | D29: 142.25 | E29: 91.29 | F29: Note 2.5 - FY26 AR p.169; FY25 AR p.158
B30: Less: interest capitalised | C30: 2.3 | D30: 17.36 | E30: 21.24 | F30: Note 2.5
B31: Unwinding of discount on provisions (non-cash) | C31: 55.36 | D31: 88.55 | E31: 95.69 | F31: Note 2.5 - relates to warranty/other provisions, not debt
B32: Interest on lease liability | C32: 3.72 | D32: 3.47 | E32: 3.99 | F32: Note 2.5
B33: Check: break-up less reported finance cost (0 = OK) | C33: =ROUND(C29-C30+C31+C32-C14,2) -> 0 | D33: =ROUND(D29-D30+D31+D32-D14,2) -> 0 | E33: =ROUND(E29-E30+E31+E32-E14,2) -> 0
A35: D. BALANCE SHEET (as at 31 March)
B36: Property, plant and equipment | C36: 4502.22 | D36: 4406.64 | E36: 5072.1 | F36: Balance Sheet - FY26 AR p.122; FY25 AR p.112; FY24 AR p.116
B37: Capital work-in-progress | C37: 95.53 | D37: 276.87 | E37: 209.98 | F37: Balance Sheet - FY26 AR p.122; FY25 AR p.112; FY24 AR p.116
B38: Right-of-use asset | C38: 235.3 | D38: 275.33 | E38: 263.04 | F38: Balance Sheet - FY26 AR p.122; FY25 AR p.112; FY24 AR p.116
B39: Goodwill | C39: 449.9 | D39: 449.9 | E39: 449.9 | F39: Balance Sheet - FY26 AR p.122; FY25 AR p.112; FY24 AR p.116
B40: Other intangible assets | C40: 764.38 | D40: 713.62 | E40: 603.83 | F40: Balance Sheet - FY26 AR p.122; FY25 AR p.112; FY24 AR p.116
B41: Intangible assets under development | C41: 106 | D41: 147.89 | E41: 269.31 | F41: Balance Sheet - FY26 AR p.122; FY25 AR p.112; FY24 AR p.116
B42: Non-current investments (mainly subsidiaries/JVs incl. Hinduja Leyland Finance) | C42: 5310.71 | D42: 5654.26 | E42: 6559.29 | F42: Balance Sheet - FY26 AR p.122; FY25 AR p.112; FY24 AR p.116 (Note 1.3)
B43: Non-current trade receivables | C43: 0.25 | D43: 0 | E43: 0 | F43: Balance Sheet - FY26 AR p.122; FY25 AR p.112; FY24 AR p.116
B44: Non-current other financial assets | C44: 64.94 | D44: 575.01 | E44: 128.4 | F44: Balance Sheet - FY26 AR p.122; FY25 AR p.112; FY24 AR p.116
...

Sheet Ratios
A1: Ashok Leyland Limited - Credit Ratios (Standalone, FY24-FY26)
A2: All cells are formulas linked to the 'Financials' and 'Debt_Analysis' sheets. 'Trend' compares FY26 with FY24: movement within ±2% is 'Stable'; direction judged against the 'Better if' column. Negative net debt = net cash.
B4: Ratio | C4: FY24 | D4: FY25 | E4: FY26 | F4: Better if | G4: Trend FY24→FY26 | H4: Definition / formula used
A5: 1. SCALE & PROFITABILITY
B6: Revenue from operations (₹ cr) | C6: =Financials!C6 -> 38367.03 | D6: =Financials!D6 -> 38752.74 | E6: =Financials!E6 -> 44007.03 | F6: Higher | G6: =IF(ABS(E6-C6)<=ABS(C6)*0.02,"Stable",IF((E6>C6)=(F6="Higher"),"Improving","Weakening")) -> Improving | H6: Statement of P&L
B7: Revenue growth (YoY) | C7: =Financials!C6/Financials!C111-1 -> 0.061500702 | D7: =Financials!D6/Financials!D111-1 -> 0.010053163 | E7: =Financials!E6/Financials!E111-1 -> 0.13558499 | F7: Higher | G7: =IF(ABS(E7-C7)<=ABS(C7)*0.02,"Stable",IF((E7>C7)=(F7="Higher"),"Improving","Weakening")) -> Improving | H7: Revenue / previous-year revenue - 1
B8: EBITDA (₹ cr) | C8: =Financials!C23 -> 4606.58 | D8: =Financials!D23 -> 4930.56 | E8: =Financials!E23 -> 5732.25 | F8: Higher | G8: =IF(ABS(E8-C8)<=ABS(C8)*0.02,"Stable",IF((E8>C8)=(F8="Higher"),"Improving","Weakening")) -> Improving | H8: Revenue - COGS - employee cost - other expenses
B9: EBITDA margin | C9: =Financials!C23/Financials!C6 -> 0.12006611 | D9: =Financials!D23/Financials!D6 -> 0.12723126 | E9: =Financials!E23/Financials!E6 -> 0.1302576 | F9: Higher | G9: =IF(ABS(E9-C9)<=ABS(C9)*0.02,"Stable",IF((E9>C9)=(F9="Higher"),"Improving","Weakening")) -> Improving | H9: EBITDA / Revenue
B10: PAT (₹ cr) | C10: =Financials!C20 -> 2617.87 | D10: =Financials!D20 -> 3303.29 | E10: =Financials!E20 -> 3565.53 | F10: Higher | G10: =IF(ABS(E10-C10)<=ABS(C10)*0.02,"Stable",IF((E10>C10)=(F10="Higher"),"Improving","Weakening")) -> Improving | H10: Profit for the year
B11: PAT margin | C11: =Financials!C20/Financials!C6 -> 0.068232282 | D11: =Financials!D20/Financials!D6 -> 0.085240166 | E11: =Financials!E20/Financials!E6 -> 0.081021828 | F11: Higher | G11: =IF(ABS(E11-C11)<=ABS(C11)*0.02,"Stable",IF((E11>C11)=(F11="Higher"),"Improving","Weakening")) -> Improving | H11: PAT / Revenue
B12: ROCE (pre-tax) | C12: =Financials!C25/(Financials!C61+Financials!C88) -> 0.35003155 | D12: =Financials!D25/(Financials!D61+Financials!D88) -> 0.32392729 | E12: =Financials!E25/(Financials!E61+Financials!E88) -> 0.35063592 | F12: Higher | G12: =IF(ABS(E12-C12)<=ABS(C12)*0.02,"Stable",IF((E12>C12)=(F12="Higher"),"Improving","Weakening")) -> Stable | H12: EBIT / (Net worth + Total debt), year-end
B13: ROE | C13: =Financials!C20/Financials!C61 -> 0.29713508 | D13: =Financials!D20/Financials!D61 -> 0.28677404 | E13: =Financials!E20/Financials!E61 -> 0.27189932 | F13: Higher | G13: =IF(ABS(E13-C13)<=ABS(C13)*0.02,"Stable",IF((E13>C13)=(F13="Higher"),"Improving","Weakening")) -> Weakening | H13: PAT / Year-end net worth
A15: 2. LEVERAGE & CAPITAL STRUCTURE
B16: Total debt incl. leases (₹ cr) | C16: =Financials!C88 -> 2299.4 | D16: =Financials!D88 -> 1481.72 | E16: =Financials!E88 -> 1195.04 | F16: Lower | G16: =IF(ABS(E16-C16)<=ABS(C16)*0.02,"Stable",IF((E16>C16)=(F16="Higher"),"Improving","Weakening")) -> Improving | H16: Borrowings (NC + current) + lease liabilities
B17: Net debt / (net cash) (₹ cr) | C17: =Financials!C88-Financials!C89 -> 108.47 | D17: =Financials!D88-Financials!D89 -> -4196.8 | E17: =Financials!E88-Financials!E89 -> -5855.76 | F17: Lower | G17: =IF(ABS(E17-C17)<=ABS(C17)*0.02,"Stable",IF((E17>C17)=(F17="Higher"),"Improving","Weakening")) -> Improving | H17: Total debt - unencumbered cash & liquid investments
B18: Total debt / Equity | C18: =Financials!C88/Financials!C61 -> 0.2609879 | D18: =Financials!D88/Financials!D61 -> 0.12863504 | E18: =Financials!E88/Financials!E61 -> 0.09113107 | F18: Lower | G18: =IF(ABS(E18-C18)<=ABS(C18)*0.02,"Stable",IF((E18>C18)=(F18="Higher"),"Improving","Weakening")) -> Improving | H18: Total debt / Net worth (matches company's own disclosed ratio: 0.26 / 0.13 / 0.09)
B19: Total debt / Tangible net worth | C19: =Financials!C88/Financials!C90 -> 0.30699231 | D19: =Financials!D88/Financials!D90 -> 0.14516164 | E19: =Financials!E88/Financials!E90 -> 0.10135721 | F19: Lower | G19: =IF(ABS(E19-C19)<=ABS(C19)*0.02,"Stable",IF((E19>C19)=(F19="Higher"),"Improving","Weakening")) -> Improving | H19: Total debt / TNW
B20: Net debt / Equity | C20: =(Financials!C88-Financials!C89)/Financials!C61 -> 0.012311628 | D20: =(Financials!D88-Financials!D89)/Financials!D61 -> -0.36434382 | E20: =(Financials!E88-Financials!E89)/Financials!E61 -> -0.44654713 | F20: Lower | G20: =IF(ABS(E20-C20)<=ABS(C20)*0.02,"Stable",IF((E20>C20)=(F20="Higher"),"Improving","Weakening")) -> Improving | H20: Negative value = net cash position
B21: TOL / TNW | C21: =Financials!C91/Financials!C90 -> 1.9761285 | D21: =Financials!D91/Financials!D90 -> 1.3722464 | E21: =Financials!E91/Financials!E90 -> 1.3129551 | F21: Lower | G21: =IF(ABS(E21-C21)<=ABS(C21)*0.02,"Stable",IF((E21>C21)=(F21="Higher"),"Improving","Weakening")) -> Improving | H21: Total outside liabilities / Tangible net worth (bank-style gearing)
B22: Total debt / EBITDA | C22: =Financials!C88/Financials!C23 -> 0.49915556 | D22: =Financials!D88/Financials!D23 -> 0.30051759 | E22: =Financials!E88/Financials!E23 -> 0.2084766 | F22: Lower | G22: =IF(ABS(E22-C22)<=ABS(C22)*0.02,"Stable",IF((E22>C22)=(F22="Higher"),"Improving","Weakening")) -> Improving | H22: Years of EBITDA needed to repay gross debt
B23: Net debt / EBITDA | C23: =(Financials!C88-Financials!C89)/Financials!C23 -> 0.023546753 | D23: =(Financials!D88-Financials!D89)/Financials!D23 -> -0.8511812 | E23: =(Financials!E88-Financials!E89)/Financials!E23 -> -1.0215465 | F23: Lower | G23: =IF(ABS(E23-C23)<=ABS(C23)*0.02,"Stable",IF((E23>C23)=(F23="Higher"),"Improving","Weakening")) -> Improving | H23: Negative = cash exceeds debt
A25: 3. DEBT SERVICING / COVERAGE
B26: Interest coverage (EBITDA / Finance cost) | C26: =Financials!C23/Financials!C14 -> 18.467688 | D26: =Financials!D23/Financials!D14 -> 22.730902 | E26: =Financials!E23/Financials!E14 -> 33.772757 | F26: Higher | G26: =IF(ABS(E26-C26)<=ABS(C26)*0.02,"Stable",IF((E26>C26)=(F26="Higher"),"Improving","Weakening")) -> Improving | H26: Uses reported finance cost, which includes non-cash unwinding of discount on provisions (conservative)
B27: EBITDA / Interest on borrowings | C27: =Financials!C23/Financials!C29 -> 23.910412 | D27: =Financials!D23/Financials!D29 -> 34.66123 | E27: =Financials!E23/Financials!E29 -> 62.791653 | F27: Higher | G27: =IF(ABS(E27-C27)<=ABS(C27)*0.02,"Stable",IF((E27>C27)=(F27="Higher"),"Improving","Weakening")) -> Improving | H27: EBITDA / gross interest expense on borrowings (before capitalisation)
B28: EBIT / Finance cost | C28: =Financials!C25/Financials!C14 -> 15.590002 | D28: =Financials!D25/Financials!D14 -> 19.414596 | E28: =Financials!E25/Financials!E14 -> 29.559064 | F28: Higher | G28: =IF(ABS(E28-C28)<=ABS(C28)*0.02,"Stable",IF((E28>C28)=(F28="Higher"),"Improving","Weakening")) -> Improving | H28: EBIT / reported finance cost
B29: DSCR (cash basis) | C29: =(Financials!C23-Financials!C97)/(Financials!C105+Financials!C101+Financials!C104) -> 2.9042528 | D29: =(Financials!D23-Financials!D97)/(Financials!D105+Financials!D101+Financials!D104) -> 4.447376 | E29: =(Financials!E23-Financials!E97)/(Financials!E105+Financials!E101+Financials!E104) -> 9.515593 | F29: Higher | G29: =IF(ABS(E29-C29)<=ABS(C29)*0.02,"Stable",IF((E29>C29)=(F29="Higher"),"Improving","Weakening")) -> Improving | H29: (EBITDA - tax paid) / (interest paid + long-term principal repaid + lease payments)
A31: 4. CASH FLOW
B32: CFO as reported (₹ cr) | C32: =Financials!C94 -> 2503.12 | D32: =Financials!D94 -> 7819.42 | E32: =Financials!E94 -> 4792.1 | F32: Higher | G32: =IF(ABS(E32-C32)<=ABS(C32)*0.02,"Stable",IF((E32>C32)=(F32="Higher"),"Improving","Weakening")) -> Improving | H32: Cash flow statement
B33: Adjusted CFO (₹ cr) | C33: =Financials!C96 -> 3956.6 | D33: =Financials!D96 -> 6365.94 | E33: =Financials!E96 -> 4792.1 | F33: Higher | G33: =IF(ABS(E33-C33)<=ABS(C33)*0.02,"Stable",IF((E33>C33)=(F33="Higher"),"Improving","Weakening")) -> Improving | H33: CFO excluding ₹1,453 cr interim-dividend account timing swing (FY24/FY25)
B34: Adjusted CFO / Total debt | C34: =Financials!C96/Financials!C88 -> 1.7207098 | D34: =Financials!D96/Financials!D88 -> 4.2963178 | E34: =Financials!E96/Financials!E88 -> 4.0099913 | F34: Higher | G34: =IF(ABS(E34-C34)<=ABS(C34)*0.02,"Stable",IF((E34>C34)=(F34="Higher"),"Improving","Weakening")) -> Improving | H34: Adjusted CFO / Total debt
B35: Capex (₹ cr) | C35: =Financials!C98 -> 495.5 | D35: =Financials!D98 -> 954.29 | E35: =Financials!E98 -> 1049.53 | F35: n.a. | G35: n.a. | H35: Purchase of PPE and intangibles
B36: Capex / Revenue | C36: =Financials!C98/Financials!C6 -> 0.012914734 | D36: =Financials!D98/Financials!D6 -> 0.024625097 | E36: =Financials!E98/Financials!E6 -> 0.023849144 | F36: n.a. | G36: n.a. | H36: Capital intensity
B37: Capex / D&A | C37: =Financials!C98/Financials!C15 -> 0.69029409 | D37: =Financials!D98/Financials!D15 -> 1.3266188 | E37: =Financials!E98/Financials!E15 -> 1.4674842 | F37: n.a. | G37: n.a. | H37: >1x means asset base is being expanded, not just maintained
B38: Free cash flow (Adj. CFO - Capex) (₹ cr) | C38: =Financials!C96-Financials!C98 -> 3461.1 | D38: =Financials!D96-Financials!D98 -> 5411.65 | E38: =Financials!E96-Financials!E98 -> 3742.57 | F38: Higher | G38: =IF(ABS(E38-C38)<=ABS(C38)*0.02,"Stable",IF((E38>C38)=(F38="Higher"),"Improving","Weakening")) -> Improving | H38: Adjusted CFO - capex
B39: FCF after dividends (₹ cr) | C39: =Financials!C96-Financials!C98-Financials!C106 -> 2697.71 | D39: =Financials!D96-Financials!D98-Financials!D106 -> 3370.88 | E39: =Financials!E96-Financials!E98-Financials!E106 -> 1907.15 | F39: Higher | G39: =IF(ABS(E39-C39)<=ABS(C39)*0.02,"Stable",IF((E39>C39)=(F39="Higher"),"Improving","Weakening")) -> Weakening | H39: FCF - dividends paid; negative = payouts funded from cash/borrowing
B40: Dividend paid / PAT | C40: =Financials!C106/Financials!C20 -> 0.2916073 | D40: =Financials!D106/Financials!D20 -> 0.61779922 | E40: =Financials!E106/Financials!E20 -> 0.51476779 | F40: n.a. | G40: n.a. | H40: Cash dividend (incl. FY24 interim paid in FY25) / PAT
A42: 5. LIQUIDITY
B43: Current ratio | C43: =Financials!C56/Financials!C78 -> 0.96334221 | D43: =Financials!D56/Financials!D78 -> 1.0772344 | E43: =Financials!E56/Financials!E78 -> 1.1002016 | F43: Higher | G43: =IF(ABS(E43-C43)<=ABS(C43)*0.02,"Stable",IF((E43>C43)=(F43="Higher"),"Improving","Weakening")) -> Improving | H43: Current assets / current liabilities
B44: Quick ratio | C44: =(Financials!C56-Financials!C48)/Financials!C78 -> 0.69829886 | D44: =(Financials!D56-Financials!D48)/Financials!D78 -> 0.81841358 | E44: =(Financials!E56-Financials!E48)/Financials!E78 -> 0.83861874 | F44: Higher | G44: =IF(ABS(E44-C44)<=ABS(C44)*0.02,"Stable",IF((E44>C44)=(F44="Higher"),"Improving","Weakening")) -> Improving | H44: (Current assets - inventory) / current liabilities
B45: Cash ratio | C45: =Financials!C89/Financials!C78 -> 0.18199557 | D45: =Financials!D89/Financials!D78 -> 0.49697667 | E45: =Financials!E89/Financials!E78 -> 0.5290756 | F45: Higher | G45: =IF(ABS(E45-C45)<=ABS(C45)*0.02,"Stable",IF((E45>C45)=(F45="Higher"),"Improving","Weakening")) -> Improving | H45: Unencumbered cash & liquid investments / current liabilities
...

Sheet Debt_Analysis
A1: Ashok Leyland Limited - Debt Composition, Maturity & Financial Risk (Standalone, ₹ crore)
A2: Blue = input from notes to accounts; Black = formula; Green = link to 'Financials' sheet.
B4: Particulars (₹ crore) | C4: FY24 | D4: FY25 | E4: FY26 | F4: Source / comment
A5: A. BORROWINGS BY INSTRUMENT (carrying value)
B6: Secured term loans from banks (non-current portion) | C6: 778.75 | D6: 636.48 | E6: 456.38 | F6: Note 1.16 - FY26 AR p.161; FY25 AR p.151
B7: Secured SIPCOT soft loan (non-current portion) | C7: 31.18 | D7: 0 | E7: 0 | F7: Note 1.16 - FY26 AR p.161; FY25 AR p.151 - fully repaid Jul-2025
B8: Secured NCDs - 7.30% AL 2027 (non-current portion) | C8: 199.33 | D8: 199.34 | E8: 0 | F8: Note 1.16 - FY26 AR p.161; FY25 AR p.151 - moved to current in FY26 (bullet 17-Mar-2027)
B9: Unsecured ECB from banks (non-current portion) | C9: 55.97 | D9: 0 | E9: 0 | F9: Note 1.16 - FY26 AR p.161; FY25 AR p.151 - ECB-16 fully repaid Nov-2025
B10: Unsecured interest-free sales tax loans (non-current) | C10: 66.41 | D10: 66.41 | E10: 61.5 | F10: Note 1.16 - FY26 AR p.161; FY25 AR p.151 - ends June 2028
B11: Non-current borrowings | C11: =SUM(C6:C10) -> 1131.64 | D11: =SUM(D6:D10) -> 902.23 | E11: =SUM(E6:E10) -> 517.88
B12: Secured short-term loans from banks | C12: 250 | D12: 0 | E12: 0 | F12: Note 1.21 - FY26 AR p.163; FY25 AR p.153
B13: Secured bills discounted | C13: 10.51 | D13: 0 | E13: 0 | F13: Note 1.21 - FY26 AR p.163; FY25 AR p.153
B14: Unsecured short-term loans from banks | C14: 150 | D14: 150 | E14: 150 | F14: Note 1.21 - FY26 AR p.163; FY25 AR p.153 - FY26: STL-29 @6.30%, due 25-Jun-2026 (Note 3.12)
B15: Unsecured bills discounted | C15: 73.8 | D15: 0 | E15: 0 | F15: Note 1.21 - FY26 AR p.163; FY25 AR p.153
B16: Current maturities of long-term debt - secured | C16: 304.69 | D16: 325.45 | E16: 478.91 | F16: Note 1.21 - FY26 AR p.163; FY25 AR p.153
B17: Current maturities of long-term debt - unsecured | C17: 333.89 | D17: 57.76 | E17: 4.91 | F17: Note 1.21 - FY26 AR p.163; FY25 AR p.153
B18: Current borrowings | C18: =SUM(C12:C17) -> 1122.89 | D18: =SUM(D12:D17) -> 533.21 | E18: =SUM(E12:E17) -> 633.82
B19: Total borrowings | C19: =C11+C18 -> 2254.53 | D19: =D11+D18 -> 1435.44 | E19: =E11+E18 -> 1151.7
B20: Check vs Balance Sheet total borrowings (0 = OK) | C20: =ROUND(C19-Financials!C87,2) -> 0 | D20: =ROUND(D19-Financials!D87,2) -> 0 | E20: =ROUND(E19-Financials!E87,2) -> 0
B21: Add: lease liabilities | C21: =Financials!C86 -> 44.87 | D21: =Financials!D86 -> 46.28 | E21: =Financials!E86 -> 43.34
B22: Total debt incl. leases | C22: =C19+C21 -> 2299.4 | D22: =D19+D21 -> 1481.72 | E22: =E19+E21 -> 1195.04
B23: Company-reported debt (capital-management note) | C23: 2299.4 | D23: 1481.72 | E23: 1195.04 | F23: Note 3.6.1 - FY26 AR p.183; FY25 AR p.171
B24: Check: our total debt - company-reported debt (0 = OK) | C24: =ROUND(C22-C23,2) -> 0 | D24: =ROUND(D22-D23,2) -> 0 | E24: =ROUND(E22-E23,2) -> 0
A26: B. DEBT MIX
B27: Secured borrowings | C27: =C6+C7+C8+C12+C13+C16 -> 1574.46 | D27: =D6+D7+D8+D12+D13+D16 -> 1161.27 | E27: =E6+E7+E8+E12+E13+E16 -> 935.29
B28: Unsecured borrowings | C28: =C9+C10+C14+C15+C17 -> 680.07 | D28: =D9+D10+D14+D15+D17 -> 274.17 | E28: =E9+E10+E14+E15+E17 -> 216.41
B29: Secured share of borrowings | C29: =C27/C19 -> 0.69835398 | D29: =D27/D19 -> 0.80899933 | E29: =E27/E19 -> 0.81209516
B30: Short-term debt (working-capital loans + bills) | C30: =SUM(C12:C15) -> 484.31 | D30: =SUM(D12:D15) -> 150 | E30: =SUM(E12:E15) -> 150
B31: Short-term debt share of borrowings | C31: =C30/C19 -> 0.21481639 | D31: =D30/D19 -> 0.10449758 | E31: =E30/E19 -> 0.13024225
B32: Variable-rate borrowings (principal) | C32: 358.75 | D32: 402 | E32: 403.13 | F32: Note 3.6.2(2) Interest-rate risk - FY26 AR p.186; FY25 AR p.174
B33: Fixed-rate borrowings (principal, incl. swapped) | C33: 1830.45 | D33: 967.69 | E33: 682.5 | F33: Note 3.6.2(2) - FY24 incl. ₹389.95 cr, FY25 ₹57.76 cr swapped to fixed
B34: Floating-rate share | C34: =C32/(C32+C33) -> 0.16387265 | D34: =D32/(D32+D33) -> 0.29349707 | E34: =E32/(E32+E33) -> 0.37133277
B35: Profit impact of +/-25 bp rate move (₹ cr, as disclosed) | C35: 0.45 | D35: 0.5 | E35: 1.01 | F35: Note 3.6.2(2)
B36: Weighted avg. interest rate - long-term loans | C36: 0.0754 | D36: 0.0722 | E36: 0.0683 | F36: Note 3.11 - FY26 AR p.203; FY25 AR p.190; FY24 AR p.189
B37: Weighted avg. interest rate - short-term borrowings | C37: 0.0739 | D37: 0.073 | E37: 0.063 | F37: Note 3.12
B38: Implied cost: gross interest / average total borrowings | C38: =Financials!C29/AVERAGE(Financials!C87,C97) -> 0.070900871 | D38: =Financials!D29/AVERAGE(Financials!D87,Financials!C87) -> 0.077100898 | E38: =Financials!E29/AVERAGE(Financials!E87,Financials!D87) -> 0.070572138 | F38: FY24 uses FY23 closing borrowings (₹3,180.10 cr, FY24 AR p.116) - see row below
A40: C. CONTRACTUAL MATURITY PROFILE (undiscounted cash flows incl. interest)
B41: Borrowings due within 1 year | C41: 1234.46 | D41: 614.03 | E41: 697.67 | F41: Note 3.6.2(C) Liquidity risk - FY26 AR p.188; FY25 AR p.176; FY24 AR p.176
B42: Borrowings due in years 2-5 | C42: 1252.74 | D42: 945.77 | E42: 558.53 | F42: Note 3.6.2(C) Liquidity risk - FY26 AR p.188; FY25 AR p.176; FY24 AR p.176
B43: Borrowings due after 5 years | C43: 0 | D43: 62.16 | E43: 16.91 | F43: Note 3.6.2(C) Liquidity risk - FY26 AR p.188; FY25 AR p.176; FY24 AR p.176
...

Sheet Consolidated_View
A1: Why the analysis uses STANDALONE numbers - consolidated snapshot (₹ crore)
A2: Consolidated accounts include Hinduja Leyland Finance (an NBFC subsidiary). Its lending book is funded by borrowings, which swamps the vehicle business's debt. The assignment excludes NBFC-style analysis, so the core credit view is on standalone Ashok Leyland; group exposure is captured through investments and guarantees.
B4: Particulars | C4: FY24 | D4: FY25 | E4: FY26 | F4: Source
B5: Revenue from operations (ex-financing income) | C5: 40956.35 | D5: 42333.28 | E5: 48313.71 | F5: Consolidated BS/P&L - FY26 AR p.220-221; FY25 AR p.208-209
B6: Income from financing operations (HLF) | C6: 4746.99 | D6: 6201.86 | E6: 8048.37 | F6: Consolidated BS/P&L - FY26 AR p.220-221; FY25 AR p.208-209
B7: Finance costs | C7: 2982.25 | D7: 3930.21 | E7: 4704.65 | F7: Consolidated BS/P&L - FY26 AR p.220-221; FY25 AR p.208-209
B8: Profit for the year (incl. NCI) | C8: 2696.34 | D8: 3382.79 | E8: 3720.98 | F8: Consolidated BS/P&L - FY26 AR p.220-221; FY25 AR p.208-209
B9: Non-current borrowings | C9: 26695.71 | D9: 36382.92 | E9: 46016.36 | F9: Consolidated BS/P&L - FY26 AR p.220-221; FY25 AR p.208-209
B10: Current borrowings | C10: 13868.63 | D10: 13318.18 | E10: 17633.44 | F10: Consolidated BS/P&L - FY26 AR p.220-221; FY25 AR p.208-209
B11: Total consolidated borrowings | C11: =C9+C10 -> 40564.34 | D11: =D9+D10 -> 49701.1 | E11: =E9+E10 -> 63649.8 | F11: Formula
B12: Total equity (incl. NCI) | C12: 11814.59 | D12: 15844.86 | E12: 18546.24 | F12: Consolidated BS/P&L - FY26 AR p.220-221; FY25 AR p.208-209
B13: Consolidated borrowings / Equity | C13: =C11/C12 -> 3.4334107 | D13: =D11/D12 -> 3.1367333 | E13: =E11/E12 -> 3.4319517 | F13: Formula
B14: Standalone borrowings (for comparison) | C14: =Financials!C87 -> 2254.53 | D14: =Financials!D87 -> 1435.44 | E14: =Financials!E87 -> 1151.7 | F14: Link
B15: Standalone share of consolidated borrowings | C15: =C14/C11 -> 0.055579112 | D15: =D14/D11 -> 0.028881453 | E15: =E14/E11 -> 0.018094322 | F15: Formula
