Workbook

Sheet 1. Company Snapshot
A1: AVENUE SUPERMARTS LIMITED (DMART) - COMPANY SNAPSHOT
A2: Consolidated financials | All figures in Rs. Crore unless stated otherwise | FY ends 31 March
A3: Source: Avenue Supermarts Ltd Annual Reports FY2023-24 (p.180-183), FY2024-25 and FY2025-26 (p.194-197). Consolidated statements used throughout.
A5: COMPANY PURPOSE AND BUSINESS MODEL
A6: DMart is an owned-store, value-retail supermarket chain operating on an Everyday Low Cost / Everyday Low Price (EDLC/EDLP) model.
A7: Revenue is driven by Foods, Non-Foods (FMCG) and General Merchandise & Apparel sold at deep discounts on high volumes and fast stock turns.
A8: The distinguishing capital-structure feature is that DMart BUYS its store real estate rather than leasing it. This converts an operating cost into
A9: an upfront capital cost, giving low rent expense and high EBITDA per store, but making the business permanently capex-hungry.
A10: Growth is therefore a funding question, not a demand question: every incremental store needs land, building and fit-out capital before it earns.
A11: As at 31 March 2026: 500 stores, 20.58 mn sq ft retail business area, 84 distribution centres, 12 packing centres across 15 states, 1 UT and NCR.
A13: Particulars | B13: FY2024 | C13: FY2025 | D13: FY2026 | E13: Source / Note
A14: A. PROFIT & LOSS (CONSOLIDATED)
A15: Revenue from operations | B15: 50788.83 | C15: 59358.05 | D15: 68820.74 | E15: Consolidated P&L, Annual Report
A16: Other income | B16: 146.45 | C16: 124.31 | D16: 74.1 | E16: Consolidated P&L, Annual Report
A17: Total income | B17: =B15+B16 -> 50935.28 | C17: =C15+C16 -> 59482.36 | D17: =D15+D16 -> 68894.84 | E17: Formula: Revenue + Other income
A18: Purchase of stock-in-trade | B18: 43958.31 | C18: 51668.76 | D18: 59315.99 | E18: Consolidated P&L, Annual Report
A19: Changes in inventories of stock-in-trade | B19: -683.77 | C19: -1117.06 | D19: -856.26 | E19: Consolidated P&L, Annual Report (negative = inventory build-up)
A20: Employee benefits expense | B20: 906.12 | C20: 1165.9 | D20: 1541.48 | E20: Consolidated P&L, Annual Report
A21: Other expenses | B21: 2504.4 | C21: 3153.12 | D21: 3632.94 | E21: Consolidated P&L, Annual Report
A22: EBITDA | B22: =B15-B18-B19-B20-B21 -> 4103.77 | C22: =C15-C18-C19-C20-C21 -> 4487.33 | D22: =D15-D18-D19-D20-D21 -> 5186.59 | E22: Formula: Revenue from operations less operating costs. Excludes Other income. Post Ind AS 116 (store rent sits in D&A and finance cost).
A23: Depreciation and amortisation expense | B23: 730.76 | C23: 869.52 | D23: 1037.02 | E23: Consolidated P&L, Annual Report
A24: EBIT | B24: =B22-B23 -> 3373.01 | C24: =C22-C23 -> 3617.81 | D24: =D22-D23 -> 4149.57 | E24: Formula: EBITDA less D&A
A25: Finance cost | B25: 58.13 | C25: 69.45 | D25: 142.05 | E25: Consolidated P&L, Annual Report. Largely interest on lease liabilities until FY25.
A26: Profit before tax | B26: =B24+B16-B25 -> 3461.33 | C26: =C24+C16-C25 -> 3672.67 | D26: =D24+D16-D25 -> 4081.62 | E26: Formula: EBIT + Other income - Finance cost. Ties to reported PBT.
A27: Total tax expense | B27: 925.72 | C27: 965.22 | D27: 1111.76 | E27: Consolidated P&L, Annual Report
A28: Profit after tax (PAT) | B28: =B26-B27 -> 2535.61 | C28: =C26-C27 -> 2707.45 | D28: =D26-D27 -> 2969.86 | E28: Formula: PBT less tax
A29: PAT attributable to owners of the Company | B29: 2536.17 | C29: 2708.02 | D29: 2970.49 | E29: Consolidated P&L, Annual Report (used for ROE)
A30: EPS - Basic (Rs.) | B30: 38.99 | C30: 41.61 | D30: 45.65 | E30: Consolidated P&L, Annual Report
A32: B. BALANCE SHEET (AS AT 31 MARCH)
A33: Equity share capital | B33: 650.73 | C33: 650.73 | D33: 651.96 | E33: Consolidated Balance Sheet, Annual Report
A34: Other equity | B34: 18047.09 | C34: 20777.02 | D34: 23812.08 | E34: Consolidated Balance Sheet, Annual Report
A35: Equity attributable to owners | B35: =B33+B34 -> 18697.82 | C35: =C33+C34 -> 21427.75 | D35: =D33+D34 -> 24464.04 | E35: Formula: Share capital + Other equity
A36: Non-controlling interest | B36: -0.48 | C36: -1.05 | D36: -1.68 | E36: Consolidated Balance Sheet, Annual Report
A37: Total equity / Net worth | B37: =B35+B36 -> 18697.34 | C37: =C35+C36 -> 21426.7 | D37: =D35+D36 -> 24462.36 | E37: Formula: Equity attributable + NCI
A38: Borrowings (current, incl. bank overdraft) | B38: 0 | C38: 0 | D38: 965.27 | E38: Consolidated Balance Sheet, Annual Report. Nil until FY25; FY26 = Rs.585 Cr short-term borrowings + Rs.380.27 Cr bank overdraft.
A39: Lease liabilities - non-current | B39: 399.24 | C39: 555.79 | D39: 1142.54 | E39: Consolidated Balance Sheet, Annual Report
A40: Lease liabilities - current | B40: 192.92 | C40: 263.83 | D40: 317.18 | E40: Consolidated Balance Sheet, Annual Report
A41: Total lease liabilities | B41: =B39+B40 -> 592.16 | C41: =C39+C40 -> 819.62 | D41: =D39+D40 -> 1459.72 | E41: Formula: Non-current + Current lease liabilities
A42: Total debt (incl. lease liabilities) | B42: =B38+B41 -> 592.16 | C42: =C38+C41 -> 819.62 | D42: =D38+D41 -> 2424.99 | E42: Formula: Borrowings + Lease liabilities. Rating agencies treat leases as debt-like.
A43: Cash and cash equivalents | B43: 337.12 | C43: 355.48 | D43: 283.71 | E43: Consolidated Balance Sheet, Annual Report
...

Sheet 2. Ratio Analysis
A1: AVENUE SUPERMARTS LIMITED (DMART) - RATIO ANALYSIS
A2: Consolidated basis. Every cell below is a live formula linked to Sheet '1. Company Snapshot' - no hardcoded ratios.
A4: Ratio | B4: Definition used | C4: FY2024 | D4: FY2025 | E4: FY2026 | F4: What it indicates
A5: A. LEVERAGE
A6: Debt-Equity (incl. lease liabilities) | B6: Total debt incl. leases / Net worth | C6: ='1. Company Snapshot'!B42/'1. Company Snapshot'!B37 -> 0.031670815 | D6: ='1. Company Snapshot'!C42/'1. Company Snapshot'!C37 -> 0.038252274 | E6: ='1. Company Snapshot'!D42/'1. Company Snapshot'!D37 -> 0.099131482 | F6: Total debt (including capitalised leases) is under a tenth of net worth. The company is funding itself almost entirely from retained earnings, so the rise from 0.03x to 0.10x reflects the start of borrowing rather than any strain.
A7: Debt-Equity (borrowings only) | B7: Borrowings / Net worth | C7: ='1. Company Snapshot'!B38/'1. Company Snapshot'!B37 -> 0 | D7: ='1. Company Snapshot'!C38/'1. Company Snapshot'!C37 -> 0 | E7: ='1. Company Snapshot'!D38/'1. Company Snapshot'!D37 -> 0.039459398 | F7: Strips out leases to show pure funded debt. Nil in FY2024 and FY2025, 0.04x in FY2026 - this is the first year DMart carried borrowings at all, which marks a genuine shift in funding policy.
A8: Net Debt / EBITDA | B8: (Total debt - cash and liquid investments) / EBITDA | C8: ='1. Company Snapshot'!B47/'1. Company Snapshot'!B22 -> -0.037204814 | D8: ='1. Company Snapshot'!C47/'1. Company Snapshot'!C22 -> 0.10254873 | E8: ='1. Company Snapshot'!D47/'1. Company Snapshot'!D22 -> 0.40859409 | F8: Moves from net cash to modest net debt as capex outpaces cash generation. The absolute level remains low, so the ratio is signalling a change in direction rather than a level of risk.
A9: Net Debt / Equity | B9: Net debt / Net worth | C9: ='1. Company Snapshot'!B47/'1. Company Snapshot'!B37 -> -0.0081658674 | D9: ='1. Company Snapshot'!C47/'1. Company Snapshot'!C37 -> 0.021476476 | E9: ='1. Company Snapshot'!D47/'1. Company Snapshot'!D37 -> 0.086631462 | F9: Cross-checks the same story against net worth. Growth is still being financed overwhelmingly out of internal accruals, not external capital.
A10: B. COVERAGE
A11: Interest Coverage (EBIT basis) | B11: EBIT / Finance cost | C11: ='1. Company Snapshot'!B24/'1. Company Snapshot'!B25 -> 58.025288 | D11: ='1. Company Snapshot'!C24/'1. Company Snapshot'!C25 -> 52.092297 | E11: ='1. Company Snapshot'!D24/'1. Company Snapshot'!D25 -> 29.212038 | F11: The fall from 58x to 29x looks steep but is arithmetic: the denominator is growing from a near-zero base. Operating profit still covers the interest charge around thirty times over.
A12: Interest Coverage (EBITDA basis) | B12: EBITDA / Finance cost | C12: ='1. Company Snapshot'!B22/'1. Company Snapshot'!B25 -> 70.596422 | D12: ='1. Company Snapshot'!C22/'1. Company Snapshot'!C25 -> 64.612383 | E12: ='1. Company Snapshot'!D22/'1. Company Snapshot'!D25 -> 36.512425 | F12: The cash-based version of coverage. It confirms that debt servicing is not a binding constraint at current or plausible future debt levels.
A13: C. PROFITABILITY AND RETURNS
A14: EBITDA margin | B14: EBITDA / Revenue from operations | C14: ='1. Company Snapshot'!B22/'1. Company Snapshot'!B15 -> 0.080800641 | D14: ='1. Company Snapshot'!C22/'1. Company Snapshot'!C15 -> 0.075597665 | E14: ='1. Company Snapshot'!D22/'1. Company Snapshot'!D15 -> 0.075363764 | F14: Margins are structurally thin because the model is deep-discount grocery - profit comes from volume and stock turn, not mark-up. The mild compression reflects a higher proportion of newly opened, not-yet-mature stores and a growing FMCG mix.
A15: PAT margin | B15: PAT / Revenue from operations | C15: ='1. Company Snapshot'!B28/'1. Company Snapshot'!B15 -> 0.04992456 | D15: ='1. Company Snapshot'!C28/'1. Company Snapshot'!C15 -> 0.045612179 | E15: ='1. Company Snapshot'!D28/'1. Company Snapshot'!D15 -> 0.043153561 | F15: Net margin narrows faster than EBITDA margin, which points to the rising depreciation and interest load created by the owned-store capex programme rather than to weakness in trading.
A16: ROCE | B16: EBIT / Average capital employed | C16: ='1. Company Snapshot'!B24/AVERAGE('1. Company Snapshot'!B70,'1. Company Snapshot'!B49) -> 0.18733085 | D16: ='1. Company Snapshot'!C24/AVERAGE('1. Company Snapshot'!B49,'1. Company Snapshot'!C49) -> 0.17420193 | E16: ='1. Company Snapshot'!D24/AVERAGE('1. Company Snapshot'!C49,'1. Company Snapshot'!D49) -> 0.16890943 | F16: Returns on capital remain well above any realistic cost of borrowing, so capital deployed into new stores is still creating value. The gradual decline is the expected drag of immature stores in the denominator.
A17: ROE | B17: PAT attributable to owners / Average equity attributable to owners | C17: ='1. Company Snapshot'!B29/AVERAGE('1. Company Snapshot'!B68,'1. Company Snapshot'!B35) -> 0.14585531 | D17: ='1. Company Snapshot'!C29/AVERAGE('1. Company Snapshot'!B35,'1. Company Snapshot'!C35) -> 0.13497727 | E17: ='1. Company Snapshot'!D29/AVERAGE('1. Company Snapshot'!C35,'1. Company Snapshot'!D35) -> 0.12945627 | F17: Falling ROE on a balance sheet with almost no leverage indicates that equity is carrying the entire capital structure. Introducing cheaper debt would mechanically lift this ratio.
A18: D. SUPPORTING INDICATORS FOR THE FUNDING DECISION
A19: Revenue growth (YoY) | B19: Current year revenue / Prior year revenue - 1 | C19: ='1. Company Snapshot'!B15/'1. Company Snapshot'!B65-1 -> 0.1855591 | D19: ='1. Company Snapshot'!C15/'1. Company Snapshot'!B15-1 -> 0.16872253 | E19: ='1. Company Snapshot'!D15/'1. Company Snapshot'!C15-1 -> 0.15941713 | F19: Sustained mid-to-high teens top-line growth across all three years, driven by store additions (365 to 500) rather than by price. This is the evidence that the expansion is demand-backed.
A20: PAT growth (YoY) | B20: Current year PAT / Prior year PAT - 1 | C20: ='1. Company Snapshot'!B28/'1. Company Snapshot'!B66-1 -> 0.066125953 | D20: ='1. Company Snapshot'!C28/'1. Company Snapshot'!B28-1 -> 0.067770675 | E20: ='1. Company Snapshot'!D28/'1. Company Snapshot'!C28-1 -> 0.096921457 | F20: Profit is growing more slowly than revenue in every year, confirming that the cost of growth - depreciation, interest and pre-maturity store losses - is currently outrunning the revenue it generates.
A21: Cash conversion (CFO / EBITDA) | B21: Net cash flow from operations / EBITDA | C21: ='1. Company Snapshot'!B53/'1. Company Snapshot'!B22 -> 0.66910183 | D21: ='1. Company Snapshot'!C53/'1. Company Snapshot'!C22 -> 0.54887205 | E21: ='1. Company Snapshot'!D53/'1. Company Snapshot'!D22 -> 0.66840448 | F21: Around two-thirds of EBITDA converts to operating cash. Earnings are cash-backed rather than accrual-driven, which is what makes a thin-margin model financeable.
A22: Capex / CFO | B22: Capital expenditure / Net cash flow from operations | C22: ='1. Company Snapshot'!B54/'1. Company Snapshot'!B53 -> 0.99468651 | D22: ='1. Company Snapshot'!C54/'1. Company Snapshot'!C53 -> 1.3898017 | E22: ='1. Company Snapshot'!D54/'1. Company Snapshot'!D53 -> 1.1865182 | F22: Capital spending equals or exceeds everything operations generate. This ratio quantifies the funding gap directly.
A23: Free cash flow (Rs. Cr) | B23: CFO less capex | C23: ='1. Company Snapshot'!B55 -> 14.59 | D23: ='1. Company Snapshot'!C55 -> -960.07 | E23: ='1. Company Snapshot'!D55 -> -646.61 | F23: Roughly breakeven in FY2024, then clearly negative as the store-addition rate stepped up. Internal accruals alone no longer cover the growth plan, which is precisely why an external raise arises.
A25: HOW TO READ THIS SHEET
A26: Green figures are live links to Sheet '1. Company Snapshot'. Change any input there and every ratio here updates. Ratios are on a consolidated, Ind AS 116 basis; lease liabilities are included in total debt because rating agencies capitalise them. ROCE and ROE use average capital employed and average equity respectively, which is why FY2023 opening balances are carried in the memo block of Sheet 1.

Sheet 3. Funding Options Matrix
A1: FUNDING OPTIONS MATRIX - SCORING OF FOUR ROUTES
A2: Each route scored 1 (worst) to 5 (best) on seven criteria. Weighted score = SUMPRODUCT of scores and weights. Rs 1,000 crore requirement.
A4: Scoring key: 5 = clearly favourable 4 = favourable 3 = neutral 2 = unfavourable 1 = clearly unfavourable
A6: Criterion | B6: Weight | C6: 1. NCD (bond) | D6: 2. Term loan | E6: 3. Commercial paper | F6: 4. QIP (equity)
A7: Cost of capital (post-tax) | B7: 0.2 | C7: 4 | D7: 3 | E7: 5 | F7: 1 | G7: NCD 5.4-5.7%; loan 5.8-6.4%; CP 4.8-5.4%; equity 11-12%
A8: Tenor match to 20-year store assets | B8: 0.2 | C8: 5 | D8: 5 | E8: 1 | F8: 5 | G8: CP must be refinanced every 90 days; all others are multi-year or permanent
A9: Rating impact | B9: 0.2 | C9: 4 | D9: 4 | E9: 1 | F9: 5 | G9: CRISIL trigger is gearing above 0.20x; CP creates refinancing risk
A10: Dilution of ownership | B10: 0.1 | C10: 5 | D10: 5 | E10: 5 | F10: 2 | G10: Only the QIP issues new shares (about 0.42%)
A11: Speed of execution | B11: 0.1 | C11: 3 | D11: 4 | E11: 5 | F11: 2 | G11: CP in days; loan 2-4 weeks; NCD 4-8 weeks; QIP needs a special resolution
A12: Control and covenants | B12: 0.1 | C12: 4 | D12: 2 | E12: 5 | F12: 2 | G12: Bank loans carry the tightest covenants; equity permanently cedes votes
A13: Market perception | B13: 0.1 | C13: 5 | D13: 3 | E13: 2 | F13: 1 | G13: Share price near a 52-week low makes an equity issue read as weakness
A14: Total weight | B14: =SUM(B7:B13) -> 1
A16: WEIGHTED SCORE | C16: =SUMPRODUCT($B$7:$B$13,C7:C13) -> 4.3 | D16: =SUMPRODUCT($B$7:$B$13,D7:D13) -> 3.8 | E16: =SUMPRODUCT($B$7:$B$13,E7:E13) -> 3.1 | F16: =SUMPRODUCT($B$7:$B$13,F7:F13) -> 2.9
A17: RANK | C17: =RANK(C16,$C$16:$F$16) -> 1 | D17: =RANK(D16,$C$16:$F$16) -> 2 | E17: =RANK(E16,$C$16:$F$16) -> 3 | F17: =RANK(F16,$C$16:$F$16) -> 4
A19: VERDICT | B19: The NCD wins because it is the only route that scores well on all three of the heavily weighted criteria at once: cost, tenor and rating impact.
A21: Note on commercial paper | B21: CP scores highest on cost and speed but is disqualified by tenor: DMart redeemed Rs 300 Cr on 7 Sep 2026 and reissued the same amount on 8 Sep 2026. Funding a 20-year store this way means repeating that cycle about 80 times.

Sheet 4. Risk Dashboard
A1: CREDIT / MARKET RISK DASHBOARD
A2: Traffic-light view. Status is formula-driven from the linked FY2026 figures and the stated threshold. Green = no concern, Amber = monitor, Red = principal risk.
A5: Risk area | B5: Measure | C5: FY2026 actual | D5: Status | E5: Threshold / benchmark | F5: Comment
A6: Leverage | B6: Debt-equity including leases | C6: ='2. Ratio Analysis'!E6 -> 0.099131482 | D6: =IF(C6>=E6,"RED",IF(C6>=E6*0.6,"AMBER","GREEN")) -> GREEN | E6: 0.2 | F6: CRISIL's published downgrade trigger is gearing above 0.20x sustained. Rose from 0.04x to 0.10x in one year; the Rs 1,000 Cr bond takes it to about 0.14x, roughly 70% of the way to the line.
A7: Leverage | B7: Net debt / EBITDA | C7: ='2. Ratio Analysis'!E8 -> 0.40859409 | D7: =IF(C7>=E7,"RED",IF(C7>=E7*0.6,"AMBER","GREEN")) -> GREEN | E7: 3 | F7: Comfortable. Under 3.0x is the normal investment-grade zone for a retailer. Moved from net cash in FY2024 to modest net debt.
A8: Coverage | B8: Interest coverage (EBIT / finance cost) | C8: ='2. Ratio Analysis'!E11 -> 29.212038 | D8: =IF(C8<=E8,"RED",IF(C8<=E8*2,"AMBER","GREEN")) -> GREEN | E8: 4 | F8: Very strong. Falls to about 19x after the bond, still far beyond any lender concern. Company's own disclosed figure for Q1 FY27 is 21.65x.
A9: Cash flow | B9: Capex / cash flow from operations | C9: ='2. Ratio Analysis'!E22 -> 1.1865182 | D9: =IF(C9>=E9,"AMBER","GREEN") -> AMBER | E9: 1 | F9: Above 100%, so spending exceeds what operations generate. Free cash flow was negative in both FY2025 and FY2026. This is the reason external funding is needed at all.
A10: Cash flow | B10: Cash conversion (CFO / EBITDA) | C10: ='2. Ratio Analysis'!E21 -> 0.66840448 | D10: =IF(C10<=E10,"RED",IF(C10<=E10*1.2,"AMBER","GREEN")) -> GREEN | E10: 0.5 | F10: Healthy. About two-thirds of operating profit converts to cash, which is what makes a thin-margin retailer financeable.
A11: Profitability | B11: EBITDA margin | C11: ='2. Ratio Analysis'!E14 -> 0.075363764 | D11: =IF(C11<=E11,"RED",IF(C11<=E11*1.15,"AMBER","GREEN")) -> AMBER | E11: 0.07 | F11: Structurally thin and slowly eroding, from 8.08% in FY2024. Employee costs rose 33% in FY2026 and revenue per sq ft fell for the first time.
A12: Dilution | B12: Promoter holding | C12: 0.7448 | D12: =IF(C12>=E12,"RED","GREEN") -> GREEN | E12: 0.75 | F12: 74.48% as on 30 June 2026, with nil shares pledged or encumbered. The recommended route issues no equity, so there is no dilution at all.
A13: Sector | B13: Online arm annual loss (Rs Cr) | C13: 307 | D13: ="RED" -> RED | E13: 0 | F13: DMart Ready has never been profitable in seven years, losing about Rs 1,235 Cr cumulatively, and the loss widened to Rs 307 Cr in FY2026. Cities cut from 24 to 11. Quick commerce is the principal structural risk.
A15: OVERALL | B15: Credit quality is strong; the risk sits in the income statement and the sector, not the balance sheet.
A17: RECOMMENDATION | B17: Raise Rs 1,000 crore through the approved and AAA-rated NCD. Hold gearing below 0.15x to keep a deliberate buffer under CRISIL's 0.20x trigger. Use part of the proceeds to clear the Rs 380 crore overdraft and stop rolling commercial paper.

Sheet 5. Recommendation Summary
A1: RECOMMENDATION SUMMARY
A2: Avenue Supermarts Limited (DMart) - Rs 1,000 crore funding requirement for store expansion capital expenditure
A4: SELECTED ROUTE | B4: Listed non-convertible debentures (NCDs) of Rs 1,000 crore, private placement, in one or more tranches
A5: Indicative pricing | B5: Fixed coupon of approximately 7.25% to 7.60%; post-tax cost of about 5.4% to 5.7%
A6: Tenor | B6: 3 to 5 years, matched against owned store assets with a 20-year life
A7: Status | B7: Board approved 11 July 2026. CRISIL assigned AAA/Stable to the instrument on 31 August 2026. No allotment filing published as at 15 September 2026, so the issue is rated but not yet placed.
A8: Why this route | B8: Cheapest capital whose tenor matches the asset, no equity dilution at a time when the share price is near a 52-week low, and the rating agency has already confirmed the company can carry it at AAA.
A10: REJECTED ALTERNATIVES
A11: Route | B11: Why rejected
A12: QIP (equity) | B12: Post-tax cost of 11-12% is roughly double the bond. Rs 1,000 Cr dilutes by only 0.42%, so the full signalling cost of an equity issue would be absorbed for very little capital, at a share price near its one-year low.
A13: Commercial paper | B13: Cheapest on rate but matures in 90 days. DMart redeemed Rs 300 Cr on 7 Sep 2026 and reissued the same amount on 8 Sep 2026. Funding 20-year assets this way creates exactly the refinancing risk rating agencies penalise.
A14: Bank term loan | B14: Viable fallback, but 50-90 bps dearer, floating rate, and carries tighter covenants and possible security over store property.
A15: Sale and leaseback | B15: Raises cash without new debt, but owning low-cost land is the source of DMart's price advantage. Ind AS 116 would also bring most of the obligation back as a lease liability.
A16: External commercial borrowing | B16: DMart earns only in rupees and has no natural hedge. Hedging back to rupees would erase the interest saving.
A17: Securitisation | B17: Not suitable. Trade receivables are Rs 149 Cr, under one day of sales, and there is no loan book. See Block E.
A19: KEY RISK AND MITIGATION
A20: Risk | B20: Description | C20: Mitigation
A21: Key risk - leverage trajectory | B21: Gearing more than doubled in FY2026 and the bond consumes about 40% of the headroom remaining before CRISIL's 0.20x downgrade trigger. Roughly Rs 1,467 Cr of capacity is left afterwards. | C21: Mitigation: size the issue to the actual annual gap rather than available capacity; set an internal ceiling of 0.15x gearing.
A22: Key risk - margin erosion | B22: EBITDA margin fell from 8.08% (FY24) to 7.54% (FY26); like-for-like growth halved from FY2023; revenue per sq ft declined for the first time. | C22: Mitigation: link further debt-funded expansion to store maturity metrics rather than to store count alone.
A23: Key risk - quick commerce | B23: DMart Ready has lost money for seven straight years, Rs 307 Cr in FY2026, and has retreated from 24 cities to 11. | C23: Mitigation: the retrenchment already caps the cash drain; monitor whether losses narrow on the smaller footprint.
A24: Key risk - refinancing | B24: Rs 965 Cr of short-term borrowings including a Rs 380 Cr overdraft, plus a rolling CP programme, sit against long-life assets. | C24: Mitigation: apply part of the bond proceeds to term out this stack, which is credit-positive on its own.
