Workbook

Sheet Questionnaire
A1: Assumption
B2: Value | D2: Time Horizon | E2: Risk-appropriate Mutual Fund Category | F2: Nifty 50 %
A3: Inflation | B3: 0.06 | D3: <= 3 years (Short-term) | E3: Debt: Liquid / Ultra Short Duration Fund | F3: 0
A4: Bank return | B4: 0.06 | D4: 5-15 years (Medium-term) | E4: Hybrid: Balanced Advantage (Medium risk) / Equity: Large & Mid Cap (High risk) | F4: 0.5
A5: Nifty 50 return | B5: 0.15 | D5: 15+ years (Long-term / Retirement) | E5: Solution-Oriented Retirement Fund, plan matched to risk profile | F5: 1
A7: QUESTIONNAIRE
A9: Basic field | B9: Options / details
A10: Name | B10: Respondent name
A11: Age | B11: Exact age
A12: Age group | B12: 20-30 / 30-40 / 40-50 / 50-60
A13: City | B13: Indian city context
A14: Salary range | B14: Below INR 8 LPA | C14: INR 8-12 LPA | D14: INR 12-18 LPA | E14: INR 18-25 LPA | F14: INR 25-40 LPA | G14: INR 40-60 LPA | H14: Above INR 60 LPA
A15: Short-term goal | B15: Optional goal based on respondent
A16: Medium-term goal | B16: Optional goal based on respondent
A17: Long term goal | B17: Optional goal based on respondent
A18: Retirement goal | B18: Compulsory for all respondents
A21: Question | B21: Option | C21: Points
A22: Under what age scale do you fall? | B22: Below 18 | C22: 5
B23: 18 to 45 | C23: 4
B24: 46 to 55 | C24: 3
B25: 56 to 65 | C25: 2
B26: 66 and above | C26: 1
A28: How much money can you take out of your monthly income for investment? | B28: 0 | C28: 1
B29: >0% <=10% | C29: 2
B30: >10% <=30% | C30: 3
B31: >30% <=50% | C31: 4
B32: >50% | C32: 5
A34: How familiar are you with stock market and concept of investment, risk and return? | B34: Not at all familiar | C34: 1
B35: Fairly familiar as I know how markets work and that stocks might be volatile and uncertain | C35: 3
B36: Very familiar as I know what to look out for before investing in any security | C36: 5
A38: How long have you been investing in stock markets? | B38: This is my first investment/Never before | C38: 1
B39: Been around 3 years | C39: 3
B40: More than 3 years | C40: 5
A42: Where do you prefer investing your money? | B42: Guaranteed income plans | C42: 1
B43: Steady growth plans | C43: 3
B44: Volatile plans with potential of very high returns | C44: 5
A46: How would you feel if the performance of your recent investments is below expectation? | B46: Panicked | C46: 1
B47: Quite uneasy | C47: 2
B48: A little concerned | C48: 3
B49: I will accept the possible highs and lows | C49: 4
...

Sheet Mutual Fund Selection
A1: Mutual Fund Selection - Detail & Rationale
A4: Persona | B4: Goal Type | C4: Goal | D4: Years | E4: Persona Risk Profile | F4: Selected Mutual Fund | G4: Category | H4: Fund Risk Appetite | I4: Expense Ratio | J4: AUM (INR Cr) | K4: 1Y Return | L4: 3Y Return | M4: 5Y Return | N4: Return % used for SIP | O4: Sharpe Ratio | P4: Monthly SIP INR
A5: Nishtha Dalal | B5: Short-term | C5: Postgraduate course fund | D5: 2 | E5: Medium | F5: HDFC Liquid Fund | G5: Debt - Liquid Fund | H5: Low | I5: 0.002 | J5: 67998.37 | K5: 0.0626 | L5: 0.0696 | M5: 0.0615 | N5: 0.0696 | O5: 0.0431 | P5: =Personas!L16 -> 17507.687
A6: Nishtha Dalal | B6: Medium-term | C6: Home purchase | D6: 10 | E6: Medium | F6: HDFC Balanced Advantage Fund | G6: Hybrid - Balanced Advantage | H6: Medium | I6: 0.0075 | J6: 104016.21 | K6: -0.0044 | L6: 0.1471 | M6: 0.1505 | N6: 0.1505 | O6: 0.0081 | P6: =Personas!L17 -> 11677.1
A7: Nishtha Dalal | B7: Long-term | C7: Retirement corpus | D7: 38 | E7: Medium | F7: Aditya Birla Sun Life Retirement Fund - The 30s Plan | G7: Solution-Oriented - Retirement Fund | H7: Mid | I7: 0.0114 | J7: 444.49 | K7: 0.094 | L7: 0.1781 | M7: 0.1227 | N7: 0.1227 | O7: 0.0077 | P7: =Personas!L18 -> 16448.222
A8: Kushagra Natani | B8: Short-term | C8: Home renovation | D8: 2 | E8: High | F8: ICICI Prudential Liquid Fund | G8: Debt - Liquid Fund | H8: Low | I8: 0.002 | J8: 58095.62 | K8: 0.0622 | L8: 0.0697 | M8: 0.0615 | N8: 0.0697 | O8: 0.0435 | P8: =Personas!L32 -> 39388.452
A9: Kushagra Natani | B9: Medium-term | C9: Home down payment | D9: 11 | E9: High | F9: ICICI Prudential Large & Mid Cap Fund | G9: Equity - Large & Mid Cap | H9: Very High | I9: 0.0076 | J9: 30146.91 | K9: 0.0023 | L9: 0.1814 | M9: 0.1762 | N9: 0.1762 | O9: 0.0087 | P9: =Personas!L33 -> 26210.026
A10: Kushagra Natani | B10: Long-term | C10: Retirement corpus | D10: 26 | E10: High | F10: Axis Retirement Fund - Dynamic Plan | G10: Solution-Oriented - Retirement Fund | H10: High | I10: 0.0129 | J10: 279.76 | K10: -0.0266 | L10: 0.1201 | M10: 0.1307 | N10: 0.1307 | O10: 0.0054 | P10: =Personas!L34 -> 55898.911
A11: Priya Mehta | B11: Short-term | C11: Child education fees | D11: 2 | E11: Medium | F11: Nippon India Liquid Fund | G11: Debt - Liquid Fund | H11: Low | I11: 0.002 | J11: 31752.32 | K11: 0.0629 | L11: 0.0701 | M11: 0.0619 | N11: 0.0701 | O11: 0.0458 | P11: =Personas!L48 -> 52497.441
A12: Priya Mehta | B12: Medium-term | C12: Child higher education fund | D12: 7 | E12: Medium | F12: SBI Balanced Advantage Fund | G12: Hybrid - Balanced Advantage | H12: Medium | I12: 0.0072 | J12: 40673.49 | K12: 0.0104 | L12: 0.1144 | N12: 0.1144 | O12: 0.0076 | P12: =Personas!L49 -> 52921.718
A13: Priya Mehta | B13: Long-term | C13: Retirement corpus | D13: 14 | E13: Medium | F13: SBI Retirement Benefit Fund - Aggressive Plan | G13: Solution-Oriented - Retirement Fund | H13: Medium | I13: 0.0093 | J13: 3000.31 | K13: -0.0521 | L13: 0.0938 | M13: 0.1258 | N13: 0.1258 | O13: 0.0035 | P13: =Personas!L50 -> 139237.83
A14: Anuj Dalal | B14: Short-term | C14: Medical contingency reserve | D14: 3 | E14: Medium | F14: ICICI Prudential Ultra Short Term Fund | G14: Debt - Ultra Short Duration | H14: Low | I14: 0.004 | J14: 16002.16 | K14: 0.0642 | L14: 0.074 | M14: 0.066 | N14: 0.074 | O14: 0.0337 | P14: =Personas!L62 -> 44473.094
A15: Anuj Dalal | B15: Medium-term | C15: Retirement transition fund | D15: 8 | E15: Medium | F15: ICICI Prudential Equity & Debt Fund | G15: Hybrid - Aggressive Hybrid | H15: Medium | I15: 0.0092 | J15: 50032.71 | K15: 0.0247 | L15: 0.1637 | M15: 0.1663 | N15: 0.1663 | O15: 0.0096 | P15: =Personas!L63 -> 80373.987
A16: Anuj Dalal | B16: Long-term | C16: Retirement safety corpus | D16: 8 | E16: Medium | F16: Tata Retirement Savings Fund - Moderate Plan | G16: Solution-Oriented - Retirement Fund | H16: Low | I16: 0.0068 | J16: 2145.42 | K16: -0.0124 | L16: 0.1374 | M16: 0.1151 | N16: 0.1151 | O16: 0.0065 | P16: =Personas!L64 -> 224173.68

Sheet Personas
A2: Assumption | B2: Value | D2: Time Horizon | E2: Risk-appropriate Mutual Fund Category | F2: Nifty 50 %
A3: Inflation | B3: 0.06 | D3: <= 3 years (Short-term) | E3: Debt: Liquid / Ultra Short Duration Fund | F3: 0
A4: Bank return | B4: 0.06 | D4: 5-15 years (Medium-term) | E4: Hybrid: Balanced Advantage (Medium risk) / Equity: Large & Mid Cap (High risk) | F4: 0.5
A5: Nifty 50 return | B5: 0.15 | D5: 15+ years (Long-term / Retirement) | E5: Solution-Oriented Retirement Fund, plan matched to risk profile | F5: 1
A7: Nishtha Dalal (20-30)
A8: Name | B8: Nishtha Dalal
A9: Age | B9: 22
A10: Age group | B10: 20-30
A11: City | B11: Mumbai
A12: Salary range | B12: INR 8-12 LPA
A13: Retirement goal | B13: Start early and build a retirement corpus by age 60.
A14: Risk profile | B14: Medium
A15: Goal type | B15: Goal | C15: Current age | D15: Target age | E15: Years | F15: Current cost INR | G15: Future cost INR | H15: Selected Mutual Fund | I15: Category | J15: Fund Risk Appetite | K15: Expected Return % | L15: Monthly SIP INR | M15: Why this fund
A16: Short-term | B16: Postgraduate course fund | C16: 22 | D16: 24 | E16: =D16-C16 -> 2 | F16: 400000 | G16: =FV($B$3,E16,0,-F16) -> 449440 | H16: HDFC Liquid Fund | I16: Debt - Liquid Fund | J16: Low | K16: 0.0696 | L16: =-PMT(K16/12,E16*12,0,G16,0) -> 17507.687 | M16: Capital safety for a 2-yr goal; near-term money kept out of market volatility.
A17: Medium-term | B17: home purchase | C17: 22 | D17: 32 | E17: =D17-C17 -> 10 | F17: 1800000 | G17: =FV($B$3,E17,0,-F17) -> 3223525.9 | H17: HDFC Balanced Advantage Fund | I17: Hybrid - Balanced Advantage | J17: Medium | K17: 0.1505 | L17: =-PMT(K17/12,E17*12,0,G17,0) -> 11677.1 | M17: Medium-risk hybrid fund balances equity growth with downside cushioning over 10 yrs.
A18: Long-term | B18: Retirement corpus | C18: 22 | D18: 60 | E18: =D18-C18 -> 38 | F18: 18000000 | G18: =FV($B$3,E18,0,-F18) -> 1.6477654e+08 | H18: Aditya Birla Sun Life Retirement Fund - The 30s Plan | I18: Solution-Oriented - Retirement Fund | J18: Mid | K18: 0.1227 | L18: =-PMT(K18/12,E18*12,0,G18,0) -> 16448.222 | M18: Equity-biased retirement plan suited to a young investor's 38-yr runway.
K20: Total | L20: =SUM(L16:L18) -> 45633.009
A23: Kushagra Natani(30-40)
A24: Name | B24: Kushagra Natani
A25: Age | B25: 34
A26: Age group | B26: 30-40
A27: City | B27: Indore
A28: Salary range | B28: INR 18-25 LPA
A29: Retirement goal | B29: Create financial independence by age 60.
A30: Risk profile | B30: High
A31: Goal type | B31: Goal | C31: Current age | D31: Target age | E31: Years | F31: Current cost INR | G31: Future cost INR | H31: Selected Mutual Fund | I31: Category | J31: Fund Risk Appetite | K31: Expected Return % | L31: Monthly SIP INR | M31: Why this fund
A32: Short-term | B32: Home renovation | C32: 34 | D32: 36 | E32: =D32-C32 -> 2 | F32: 900000 | G32: =FV($B$3,E32,0,-F32) -> 1011240 | H32: ICICI Prudential Liquid Fund | I32: Debt - Liquid Fund | J32: Low | K32: 0.0697 | L32: =-PMT(K32/12,E32*12,0,G32,0) -> 39388.452 | M32: Capital safety for a 2-yr goal; near-term money kept out of market volatility.
A33: Medium-term | B33: Home down payment | C33: 34 | D33: 45 | E33: =D33-C33 -> 11 | F33: 5500000 | G33: =FV($B$3,E33,0,-F33) -> 10440642 | H33: ICICI Prudential Large & Mid Cap Fund | I33: Equity - Large & Mid Cap | J33: Very High | K33: 0.1762 | L33: =-PMT(K33/12,E33*12,0,G33,0) -> 26210.026 | M33: High risk appetite + 11-yr horizon supports a pure-equity large & mid cap allocation.
A34: Long-term | B34: Retirement corpus | C34: 34 | D34: 60 | E34: =D34-C34 -> 26 | F34: 32000000 | G34: =FV($B$3,E34,0,-F34) -> 1.4558025e+08 | H34: Axis Retirement Fund - Dynamic Plan | I34: Solution-Oriented - Retirement Fund | J34: High | K34: 0.1307 | L34: =-PMT(K34/12,E34*12,0,G34,0) -> 55898.911 | M34: Aggressive retirement plan matching a high risk profile and 26-yr horizon.
K36: Total | L36: =SUM(L32:L34) -> 121497.39
A39: Priya Mehta (40-50)
A40: Name | B40: Priya Mehta
A41: Age | B41: 46
A42: Age group | B42: 40-50
A43: City | B43: Delhi NCR
A44: Salary range | B44: INR 25-40 LPA
A45: Retirement goal | B45: Protect retirement comfort while funding child's education.
A46: Risk profile | B46: Medium
A47: Goal type | B47: Goal | C47: Current age | D47: Target age | E47: Years | F47: Current cost INR | G47: Future cost INR | H47: Selected Mutual Fund | I47: Category | J47: Fund Risk Appetite | K47: Expected Return % | L47: Monthly SIP INR | M47: Why this fund
A48: Short-term | B48: Child education fees | C48: 46 | D48: 48 | E48: =D48-C48 -> 2 | F48: 1200000 | G48: =FV($B$3,E48,0,-F48) -> 1348320 | H48: Nippon India Liquid Fund | I48: Debt - Liquid Fund | J48: Low | K48: 0.0701 | L48: =-PMT(K48/12,E48*12,0,G48,0) -> 52497.441 | M48: Capital safety for a 2-yr goal; near-term money kept out of market volatility.
...
